{"uuid": "8b3116e8-40cb-464a-ba13-dc730981f57c", "children": ["bcbfd7f0-9a40-4ea1-a291-eae054d26759"], "befores": [{"name": "driver", "status": "passed", "start": 1644222663948, "stop": 1644222715630}], "afters": [{"name": "driver::0", "status": "broken", "statusDetails": {"message": "selenium.common.exceptions.WebDriverException: Message: Invalid session id\n\n", "trace": "  File \"/home/headspin/.local/lib/python3.8/site-packages/allure_commons/_allure.py\", line 200, in __call__\n    return self._fixture_function(*args, **kwargs)\n  File \"/home/headspin/.local/lib/python3.8/site-packages/_pytest/fixtures.py\", line 941, in _teardown_yield_fixture\n    next(it)\n  File \"/home/headspin/Documents/maps/io/headspin/maps/conftest.py\", line 74, in driver\n    tearDown(get_args, driver)\n  File \"/home/headspin/Documents/maps/io/headspin/maps/conftest.py\", line 81, in tearDown\n    driver.terminate_app(self.package)\n  File \"/home/headspin/.local/lib/python3.8/site-packages/appium/webdriver/extensions/applications.py\", line 146, in terminate_app\n    return self.execute(Command.TERMINATE_APP, data)['value']\n  File \"/home/headspin/.local/lib/python3.8/site-packages/selenium/webdriver/remote/webdriver.py\", line 424, in execute\n    self.error_handler.check_response(response)\n  File \"/home/headspin/.local/lib/python3.8/site-packages/appium/webdriver/errorhandler.py\", line 31, in check_response\n    raise wde\n  File \"/home/headspin/.local/lib/python3.8/site-packages/appium/webdriver/errorhandler.py\", line 26, in check_response\n    super().check_response(response)\n  File \"/home/headspin/.local/lib/python3.8/site-packages/selenium/webdriver/remote/errorhandler.py\", line 247, in check_response\n    raise exception_class(message, screen, stacktrace)\n"}, "start": 1644222716078, "stop": 1644222716418}], "start": 1644222663948, "stop": 1644222716419}