{"uuid": "4c99f4fd-2f76-4035-86e8-b2e1b9ff046f", "children": ["bc9cdcc6-f9d8-4484-9ef2-eb4664be4353"], "befores": [{"name": "driver", "status": "broken", "statusDetails": {"message": "urllib3.exceptions.MaxRetryError: HTTPSConnectionPool(host='dev-us-nyc-0.headspin.io', port=7008): Max retries exceeded with url: /v0/7bb42a99111c486aa79677de182498b0/wd/hub/session (Caused by NewConnectionError('<urllib3.connection.VerifiedHTTPSConnection object at 0x7f2d4d5803d0>: Failed to establish a new connection: [Errno 111] Connection refused'))\n", "trace": "  File \"/home/headspin/.local/lib/python3.8/site-packages/pluggy/_callers.py\", line 39, in _multicall\n    res = hook_impl.function(*args)\n  File \"/home/headspin/.local/lib/python3.8/site-packages/_pytest/fixtures.py\", line 1126, in pytest_fixture_setup\n    result = call_fixture_func(fixturefunc, request, kwargs)\n  File \"/home/headspin/.local/lib/python3.8/site-packages/_pytest/fixtures.py\", line 925, in call_fixture_func\n    fixture_result = next(generator)\n  File \"/home/headspin/Documents/maps/io/headspin/maps/conftest.py\", line 44, in driver\n    driver = webdriver.Remote(\n  File \"/home/headspin/.local/lib/python3.8/site-packages/appium/webdriver/webdriver.py\", line 273, in __init__\n    super().__init__(\n  File \"/home/headspin/.local/lib/python3.8/site-packages/selenium/webdriver/remote/webdriver.py\", line 268, in __init__\n    self.start_session(capabilities, browser_profile)\n  File \"/home/headspin/.local/lib/python3.8/site-packages/appium/webdriver/webdriver.py\", line 364, in start_session\n    response = self.execute(RemoteCommand.NEW_SESSION, parameters)\n  File \"/home/headspin/.local/lib/python3.8/site-packages/selenium/webdriver/remote/webdriver.py\", line 422, in execute\n    response = self.command_executor.execute(driver_command, params)\n  File \"/home/headspin/.local/lib/python3.8/site-packages/selenium/webdriver/remote/remote_connection.py\", line 421, in execute\n    return self._request(command_info[0], url, body=data)\n  File \"/home/headspin/.local/lib/python3.8/site-packages/selenium/webdriver/remote/remote_connection.py\", line 443, in _request\n    resp = self._conn.request(method, url, body=body, headers=headers)\n  File \"/usr/lib/python3/dist-packages/urllib3/request.py\", line 79, in request\n    return self.request_encode_body(\n  File \"/usr/lib/python3/dist-packages/urllib3/request.py\", line 171, in request_encode_body\n    return self.urlopen(method, url, **extra_kw)\n  File \"/usr/lib/python3/dist-packages/urllib3/poolmanager.py\", line 330, in urlopen\n    response = conn.urlopen(method, u.request_uri, **kw)\n  File \"/usr/lib/python3/dist-packages/urllib3/connectionpool.py\", line 747, in urlopen\n    return self.urlopen(\n  File \"/usr/lib/python3/dist-packages/urllib3/connectionpool.py\", line 747, in urlopen\n    return self.urlopen(\n  File \"/usr/lib/python3/dist-packages/urllib3/connectionpool.py\", line 747, in urlopen\n    return self.urlopen(\n  File \"/usr/lib/python3/dist-packages/urllib3/connectionpool.py\", line 719, in urlopen\n    retries = retries.increment(\n  File \"/usr/lib/python3/dist-packages/urllib3/util/retry.py\", line 436, in increment\n    raise MaxRetryError(_pool, url, error or ResponseError(cause))\n"}, "start": 1644222663781, "stop": 1644222664867}], "start": 1644222663781, "stop": 1644222665044}