[33mWARNING [0m urllib3.connectionpool:connectionpool.py:744 Retrying (Retry(total=2, connect=None, read=None, redirect=None, status=None)) after connection broken by 'NewConnectionError('<urllib3.connection.VerifiedHTTPSConnection object at 0x7f2d4d5dec10>: Failed to establish a new connection: [Errno 111] Connection refused')': /v0/7bb42a99111c486aa79677de182498b0/wd/hub/session
[33mWARNING [0m urllib3.connectionpool:connectionpool.py:744 Retrying (Retry(total=1, connect=None, read=None, redirect=None, status=None)) after connection broken by 'NewConnectionError('<urllib3.connection.VerifiedHTTPSConnection object at 0x7f2d4d5801c0>: Failed to establish a new connection: [Errno 111] Connection refused')': /v0/7bb42a99111c486aa79677de182498b0/wd/hub/session
[33mWARNING [0m urllib3.connectionpool:connectionpool.py:744 Retrying (Retry(total=0, connect=None, read=None, redirect=None, status=None)) after connection broken by 'NewConnectionError('<urllib3.connection.VerifiedHTTPSConnection object at 0x7f2d4d5802b0>: Failed to establish a new connection: [Errno 111] Connection refused')': /v0/7bb42a99111c486aa79677de182498b0/wd/hub/session